Workbook

Sheet Resumen
A1: Planilla ampliada de intenciones y conversaciones para agenda por WhatsApp
A3: Objetivo | B3: Cubrir comprensión lingüística, contexto de varios turnos, extracción de entidades, decisiones seguras y pruebas para reservar, consultar, reprogramar y cancelar. | C3: Alcance | D3: Empresa, sucursal, profesional, servicio, fecha, hora, disponibilidad y múltiples clientes.
A4: Versión | B4: 2.0 ampliada | C4: Fecha de actualización | D4: 2026-07-26
A5: Ejemplos originales | B5: =COUNTA(Reservar!A:A)-1+COUNTA(Reprogramar!A:A)-1+COUNTA(Cancelar!A:A)-1 | C5: Intenciones catalogadas | D5: =COUNTA(Taxonomia_Intenciones!A:A)-1
A6: Ejemplos ampliados | B6: =COUNTA(Ejemplos_Ampliados!A:A)-1 | C6: Escenarios multiconversación | D6: =COUNTA(Escenarios_Multiturno!A:A)-1
A7: Turnos conversacionales | B7: =COUNTA(Conversaciones_Multiturno!A:A)-1 | C7: Ejemplos de entidades | D7: =COUNTA(Entidades_Estructuradas!A:A)-1
A8: Casos negativos | B8: =COUNTA(Casos_Negativos!A:A)-1 | C8: Referencias contextuales | D8: =COUNTA(Contexto_Referencias!A:A)-1
A9: Cambios de intención | B9: =COUNTA(Cambios_Intencion!A:A)-1 | C9: Casos con varias reservas | D9: =COUNTA(Multiples_Reservas!A:A)-1
A10: Reglas de respuesta y acción | B10: =COUNTA(Respuestas_Acciones!A:A)-1 | C10: Estados conversacionales | D10: =COUNTA(Estados_Conversacion!A:A)-1
A11: Casos de evaluación | B11: =COUNTA(Evaluacion_Dataset!A:A)-1 | C11: Uso recomendado | D11: Clasificador de intención, extracción de entidades, pruebas automatizadas y contexto para un modelo de lenguaje.
A12: Límite de seguridad | B12: La planilla no reemplaza las validaciones transaccionales de disponibilidad, pertenencia a empresa, políticas de cancelación ni concurrencia. | C12: Fuente complementaria | D12: Utilizar junto con WhatsAppBooking.xlsx para reglas de negocio y concurrencia.

Sheet Reservar
A1: ID | B1: Intención | C1: Subcategoría | D1: Término o frase | E1: Ejemplo de WhatsApp | F1: Nivel de confianza | G1: Tipo de expresión | H1: País o región sugerida | I1: Entidades a extraer | J1: Acción sugerida | K1: Regla de clasificación sugerida | L1: Observaciones | M1: Fuente URL
A2: RES-001 | B2: reservar | C2: sinónimo o frase principal | D2: reservar | E2: Hola, quiero reservar para mañana | F2: Alta | G2: directa | H2: General | I2: servicio, fecha, hora, sucursal, profesional, nombre, teléfono | J2: Consultar disponibilidad y proponer horarios | K2: Activar reservar si aparece verbo de creación de cita/reserva sin negación | L2: Término de alta utilidad para inicio de flujo de agenda | M2: https://help.reservio.com/es/articles/5113656-como-crear-reservas-para-citas-individuales
A3: RES-002 | B3: reservar | C3: sinónimo o frase principal | D3: agendar | E3: Quiero agendar una hora | F3: Alta | G3: directa | H3: Chile / Latinoamérica | I3: servicio, fecha, hora, sucursal, profesional, nombre, teléfono | J3: Consultar disponibilidad y proponer horarios | K3: Activar reservar si aparece verbo de creación de cita/reserva sin negación | L3: Término de alta utilidad para inicio de flujo de agenda | M3: https://www.asisa.es/preguntas-frecuentes/area-privada/pedir-cita/puedo-pedir-cita-on-line
A4: RES-003 | B4: reservar | C4: sinónimo o frase principal | D4: programar cita | E4: Necesito programar una cita para esta semana | F4: Alta | G4: directa | H4: General | I4: servicio, fecha, hora, sucursal, profesional, nombre, teléfono | J4: Consultar disponibilidad y proponer horarios | K4: Activar reservar si aparece verbo de creación de cita/reserva sin negación | L4: Término de alta utilidad para inicio de flujo de agenda | M4: https://help.acuityscheduling.com/hc/es/articles/16676870828685-Reservar-citas-para-los-clientes
A5: RES-004 | B5: reservar | C5: sinónimo o frase principal | D5: pedir cita | E5: Buenas, quiero pedir cita con la doctora | F5: Alta | G5: directa | H5: España / Salud | I5: servicio, fecha, hora, sucursal, profesional, nombre, teléfono | J5: Consultar disponibilidad y proponer horarios | K5: Activar reservar si aparece verbo de creación de cita/reserva sin negación | L5: Término de alta utilidad para inicio de flujo de agenda | M5: https://www.asisa.es/preguntas-frecuentes/area-privada/pedir-cita/puedo-pedir-cita-on-line
A6: RES-005 | B6: reservar | C6: sinónimo o frase principal | D6: solicitar cita | E6: Deseo solicitar una cita online | F6: Alta | G6: formal | H6: General | I6: servicio, fecha, hora, sucursal, profesional, nombre, teléfono | J6: Consultar disponibilidad y proponer horarios | K6: Activar reservar si aparece verbo de creación de cita/reserva sin negación | L6: Término de alta utilidad para inicio de flujo de agenda | M6: https://sede.dgt.gob.es/es/otros-tramites/cita-previa/index.html
A7: RES-006 | B7: reservar | C7: sinónimo o frase principal | D7: pedir hora | E7: Hola, quiero pedir hora para limpieza facial | F7: Alta | G7: coloquial | H7: Chile | I7: servicio, fecha, hora, sucursal, profesional, nombre, teléfono | J7: Consultar disponibilidad y proponer horarios | K7: Activar reservar si aparece verbo de creación de cita/reserva sin negación | L7: Término de alta utilidad para inicio de flujo de agenda | M7: https://agendapro.com/blog/transformar-conversaciones-de-whatsapp-en-reservas/
A8: RES-007 | B8: reservar | C8: sinónimo o frase principal | D8: tomar hora | E8: Necesito tomar hora para el viernes | F8: Alta | G8: coloquial | H8: Chile | I8: servicio, fecha, hora, sucursal, profesional, nombre, teléfono | J8: Consultar disponibilidad y proponer horarios | K8: Activar reservar si aparece verbo de creación de cita/reserva sin negación | L8: Término de alta utilidad para inicio de flujo de agenda | M8: https://agendapro.com/blog/transformar-conversaciones-de-whatsapp-en-reservas/
A9: RES-008 | B9: reservar | C9: sinónimo o frase principal | D9: sacar hora | E9: Puedo sacar hora para manicure | F9: Media | G9: coloquial | H9: Chile | I9: servicio, fecha, hora, sucursal, profesional, nombre, teléfono | J9: Consultar disponibilidad y proponer horarios | K9: Activar reservar si aparece verbo de creación de cita/reserva sin negación | L9: Término de alta utilidad para inicio de flujo de agenda | M9: https://agendapro.com/blog/transformar-conversaciones-de-whatsapp-en-reservas/
A10: RES-009 | B10: reservar | C10: sinónimo o frase principal | D10: sacar turno | E10: Quiero sacar turno para mañana | F10: Alta | G10: coloquial | H10: Argentina / Uruguay | I10: servicio, fecha, hora, sucursal, profesional, nombre, teléfono | J10: Consultar disponibilidad y proponer horarios | K10: Activar reservar si aparece verbo de creación de cita/reserva sin negación | L10: Término de alta utilidad para inicio de flujo de agenda | M10: https://www.doctoralia.es/faq/consulta-online
A11: RES-010 | B11: reservar | C11: sinónimo o frase principal | D11: tomar turno | E11: Me gustaría tomar turno con la especialista | F11: Media | G11: coloquial | H11: Argentina / Uruguay | I11: servicio, fecha, hora, sucursal, profesional, nombre, teléfono | J11: Consultar disponibilidad y proponer horarios | K11: Activar reservar si aparece verbo de creación de cita/reserva sin negación | L11: Término de alta utilidad para inicio de flujo de agenda | M11: https://www.doctoralia.es/faq/consulta-online
A12: RES-011 | B12: reservar | C12: sinónimo o frase principal | D12: pedir turno | E12: Hola, quería pedir turno | F12: Alta | G12: coloquial | H12: Argentina / Uruguay | I12: servicio, fecha, hora, sucursal, profesional, nombre, teléfono | J12: Consultar disponibilidad y proponer horarios | K12: Activar reservar si aparece verbo de creación de cita/reserva sin negación | L12: Término de alta utilidad para inicio de flujo de agenda | M12: https://www.doctoralia.es/faq/consulta-online
... A74: RES-073 | B74: reservar | C74: señal temporal o urgencia | D74: después de la pega | E74: ¿Hay hora después de la pega? | F74: Media | G74: coloquial | H74: Chile / Latinoamérica | I74: fecha relativa, tramo horario, urgencia, servicio | J74: Resolver fecha/hora y consultar disponibilidad | K74: Activar reservar cuando la urgencia esté conectada a hora/cita/servicio | L74: La urgencia modifica prioridad pero no reemplaza validaciones de disponibilidad | M74: https://agendapro.com/blog/confirmaciones-automaticas-por-whatsapp/

Sheet Reprogramar
A1: ID | B1: Intención | C1: Subcategoría | D1: Término o frase | E1: Ejemplo de WhatsApp | F1: Nivel de confianza | G1: Tipo de expresión | H1: País o región sugerida | I1: Entidades a extraer | J1: Acción sugerida | K1: Regla de clasificación sugerida | L1: Observaciones | M1: Fuente URL
A2: REP-001 | B2: reprogramar | C2: sinónimo o frase principal | D2: reprogramar | E2: Hola, necesito reprogramar mi cita | F2: Alta | G2: directa | H2: General | I2: cita existente, fecha actual, nueva fecha, nueva hora, motivo, cliente | J2: Buscar cita existente y consultar nueva disponibilidad | K2: Activar reprogramar si hay verbo de cambio aplicado a cita/reserva/sesión/hora | L2: Debe existir una reserva previa o solicitar datos para identificarla | M2: https://help.calendly.com/hc/es/articles/14079031268375-C%C3%B3mo-cancelar-reprogramar-y-realizar-cambios-en-un-evento
A3: REP-002 | B3: reprogramar | C3: sinónimo o frase principal | D3: reagendar | E3: Quiero reagendar mi hora | F3: Alta | G3: directa | H3: Chile / Latinoamérica | I3: cita existente, fecha actual, nueva fecha, nueva hora, motivo, cliente | J3: Buscar cita existente y consultar nueva disponibilidad | K3: Activar reprogramar si hay verbo de cambio aplicado a cita/reserva/sesión/hora | L3: Debe existir una reserva previa o solicitar datos para identificarla | M3: https://ayuda.encuadrado.com/es/articles/5539645-como-reagendar-a-un-consultante
A4: REP-003 | B4: reprogramar | C4: sinónimo o frase principal | D4: cambiar cita | E4: Necesito cambiar mi cita | F4: Alta | G4: directa | H4: General | I4: cita existente, fecha actual, nueva fecha, nueva hora, motivo, cliente | J4: Buscar cita existente y consultar nueva disponibilidad | K4: Activar reprogramar si hay verbo de cambio aplicado a cita/reserva/sesión/hora | L4: Debe existir una reserva previa o solicitar datos para identificarla | M4: https://help.acuityscheduling.com/hc/es/articles/16676869573645-C%C3%B3mo-reservan-citas-los-clientes
A5: REP-004 | B5: reprogramar | C5: sinónimo o frase principal | D5: cambiar hora | E5: Quiero cambiar la hora de mi reserva | F5: Alta | G5: directa | H5: Chile / General | I5: cita existente, fecha actual, nueva fecha, nueva hora, motivo, cliente | J5: Buscar cita existente y consultar nueva disponibilidad | K5: Activar reprogramar si hay verbo de cambio aplicado a cita/reserva/sesión/hora | L5: Debe existir una reserva previa o solicitar datos para identificarla | M5: https://ayuda.encuadrado.com/es/articles/5539645-como-reagendar-a-un-consultante
A6: REP-005 | B6: reprogramar | C6: sinónimo o frase principal | D6: cambiar fecha | E6: ¿Puedo cambiar la fecha de la cita? | F6: Alta | G6: directa | H6: General | I6: cita existente, fecha actual, nueva fecha, nueva hora, motivo, cliente | J6: Buscar cita existente y consultar nueva disponibilidad | K6: Activar reprogramar si hay verbo de cambio aplicado a cita/reserva/sesión/hora | L6: Debe existir una reserva previa o solicitar datos para identificarla | M6: https://support.wix.com/es/article/wix-bookings-permitir-a-los-clientes-cancelar-o-reprogramar-sesiones
A7: REP-006 | B7: reprogramar | C7: sinónimo o frase principal | D7: modificar cita | E7: Necesito modificar mi cita | F7: Alta | G7: formal | H7: General | I7: cita existente, fecha actual, nueva fecha, nueva hora, motivo, cliente | J7: Buscar cita existente y consultar nueva disponibilidad | K7: Activar reprogramar si hay verbo de cambio aplicado a cita/reserva/sesión/hora | L7: Debe existir una reserva previa o solicitar datos para identificarla | M7: https://help.reservio.com/es/articles/5113656-como-crear-reservas-para-citas-individuales
A8: REP-007 | B8: reprogramar | C8: sinónimo o frase principal | D8: modificar reserva | E8: Quiero modificar mi reserva | F8: Alta | G8: formal | H8: General | I8: cita existente, fecha actual, nueva fecha, nueva hora, motivo, cliente | J8: Buscar cita existente y consultar nueva disponibilidad | K8: Activar reprogramar si hay verbo de cambio aplicado a cita/reserva/sesión/hora | L8: Debe existir una reserva previa o solicitar datos para identificarla | M8: https://help.reservio.com/es/articles/5113656-como-crear-reservas-para-citas-individuales
A9: REP-008 | B9: reprogramar | C9: sinónimo o frase principal | D9: editar reserva | E9: ¿Se puede editar mi reserva? | F9: Media | G9: formal | H9: General | I9: cita existente, fecha actual, nueva fecha, nueva hora, motivo, cliente | J9: Buscar cita existente y consultar nueva disponibilidad | K9: Activar reprogramar si hay verbo de cambio aplicado a cita/reserva/sesión/hora | L9: Debe existir una reserva previa o solicitar datos para identificarla | M9: https://help.acuityscheduling.com/hc/es/articles/16676870828685-Reservar-citas-para-los-clientes
A10: REP-009 | B10: reprogramar | C10: sinónimo o frase principal | D10: mover cita | E10: ¿Pueden mover mi cita al viernes? | F10: Alta | G10: coloquial | H10: General | I10: cita existente, fecha actual, nueva fecha, nueva hora, motivo, cliente | J10: Buscar cita existente y consultar nueva disponibilidad | K10: Activar reprogramar si hay verbo de cambio aplicado a cita/reserva/sesión/hora | L10: Debe existir una reserva previa o solicitar datos para identificarla | M10: https://agendapro.com/blog/transformar-conversaciones-de-whatsapp-en-reservas/
A11: REP-010 | B11: reprogramar | C11: sinónimo o frase principal | D11: mover hora | E11: Necesito mover la hora para más tarde | F11: Alta | G11: coloquial | H11: Chile | I11: cita existente, fecha actual, nueva fecha, nueva hora, motivo, cliente | J11: Buscar cita existente y consultar nueva disponibilidad | K11: Activar reprogramar si hay verbo de cambio aplicado a cita/reserva/sesión/hora | L11: Debe existir una reserva previa o solicitar datos para identificarla | M11: https://agendapro.com/blog/transformar-conversaciones-de-whatsapp-en-reservas/
A12: REP-011 | B12: reprogramar | C12: sinónimo o frase principal | D12: correr cita | E12: ¿Podemos correr la cita para mañana? | F12: Media | G12: coloquial | H12: Latinoamérica | I12: cita existente, fecha actual, nueva fecha, nueva hora, motivo, cliente | J12: Buscar cita existente y consultar nueva disponibilidad | K12: Activar reprogramar si hay verbo de cambio aplicado a cita/reserva/sesión/hora | L12: Debe existir una reserva previa o solicitar datos para identificarla | M12: https://agendapro.com/blog/transformar-conversaciones-de-whatsapp-en-reservas/
... A68: REP-067 | B68: reprogramar | C68: señal temporal urgencia o motivo | D68: reagendar sin perder abono | E68: Necesito reagendar sin perder el abono | F68: Media | G68: intención compuesta | H68: WhatsApp / General | I68: motivo, cita existente, nueva fecha, nueva hora, pago/abono | J68: Aplicar política de reprogramación y consultar disponibilidad | K68: Si hay imposibilidad de asistir pero deseo de mantener atención, activar reprogramar | L68: Revisar reglas de anticipación y cargos antes de confirmar | M68: https://biz.booksy.com/es-es/blog/politica-de-cancelacion-y-no-show-para-salones

Sheet Cancelar
A1: ID | B1: Intención | C1: Subcategoría | D1: Término o frase | E1: Ejemplo de WhatsApp | F1: Nivel de confianza | G1: Tipo de expresión | H1: País o región sugerida | I1: Entidades a extraer | J1: Acción sugerida | K1: Regla de clasificación sugerida | L1: Observaciones | M1: Fuente URL
A2: CAN-001 | B2: cancelar | C2: sinónimo o frase principal | D2: cancelar | E2: Hola, quiero cancelar mi cita | F2: Alta | G2: directa | H2: General | I2: cita existente, motivo, política de cancelación, pago/abono | J2: Buscar cita existente y pedir confirmación antes de cancelar | K2: Activar cancelar si hay verbo de eliminación/anulación/no asistencia aplicado a cita/reserva/hora | L2: Debe requerir confirmación explícita antes de ejecutar acción irreversible | M2: https://help.calendly.com/hc/es/articles/14079031268375-C%C3%B3mo-cancelar-reprogramar-y-realizar-cambios-en-un-evento
A3: CAN-002 | B3: cancelar | C3: sinónimo o frase principal | D3: anular | E3: Necesito anular la reserva | F3: Alta | G3: formal | H3: España / Chile / General | I3: cita existente, motivo, política de cancelación, pago/abono | J3: Buscar cita existente y pedir confirmación antes de cancelar | K3: Activar cancelar si hay verbo de eliminación/anulación/no asistencia aplicado a cita/reserva/hora | L3: Debe requerir confirmación explícita antes de ejecutar acción irreversible | M3: https://sede.dgt.gob.es/es/otros-tramites/cita-previa/index.html
A4: CAN-003 | B4: cancelar | C4: sinónimo o frase principal | D4: cancelar cita | E4: Quiero cancelar cita para mañana | F4: Alta | G4: directa | H4: General | I4: cita existente, motivo, política de cancelación, pago/abono | J4: Buscar cita existente y pedir confirmación antes de cancelar | K4: Activar cancelar si hay verbo de eliminación/anulación/no asistencia aplicado a cita/reserva/hora | L4: Debe requerir confirmación explícita antes de ejecutar acción irreversible | M4: https://www.doctoralia.es/faq/consulta-online
A5: CAN-004 | B5: cancelar | C5: sinónimo o frase principal | D5: cancelar reserva | E5: Deseo cancelar mi reserva | F5: Alta | G5: directa | H5: General | I5: cita existente, motivo, política de cancelación, pago/abono | J5: Buscar cita existente y pedir confirmación antes de cancelar | K5: Activar cancelar si hay verbo de eliminación/anulación/no asistencia aplicado a cita/reserva/hora | L5: Debe requerir confirmación explícita antes de ejecutar acción irreversible | M5: https://help.reservio.com/es/articles/5113819-cancelar-una-reserva-citas-individuales
A6: CAN-005 | B6: cancelar | C6: sinónimo o frase principal | D6: cancelar hora | E6: Quiero cancelar la hora del viernes | F6: Alta | G6: directa | H6: Chile | I6: cita existente, motivo, política de cancelación, pago/abono | J6: Buscar cita existente y pedir confirmación antes de cancelar | K6: Activar cancelar si hay verbo de eliminación/anulación/no asistencia aplicado a cita/reserva/hora | L6: Debe requerir confirmación explícita antes de ejecutar acción irreversible | M6: https://agendapro.com/blog/confirmaciones-automaticas-por-whatsapp/
A7: CAN-006 | B7: cancelar | C7: sinónimo o frase principal | D7: cancelar turno | E7: Necesito cancelar mi turno | F7: Alta | G7: directa | H7: Argentina / Uruguay | I7: cita existente, motivo, política de cancelación, pago/abono | J7: Buscar cita existente y pedir confirmación antes de cancelar | K7: Activar cancelar si hay verbo de eliminación/anulación/no asistencia aplicado a cita/reserva/hora | L7: Debe requerir confirmación explícita antes de ejecutar acción irreversible | M7: https://www.doctoralia.es/faq/consulta-online
A8: CAN-007 | B8: cancelar | C8: sinónimo o frase principal | D8: anular cita | E8: Solicito anular mi cita | F8: Alta | G8: formal | H8: General | I8: cita existente, motivo, política de cancelación, pago/abono | J8: Buscar cita existente y pedir confirmación antes de cancelar | K8: Activar cancelar si hay verbo de eliminación/anulación/no asistencia aplicado a cita/reserva/hora | L8: Debe requerir confirmación explícita antes de ejecutar acción irreversible | M8: https://sede.dgt.gob.es/es/otros-tramites/cita-previa/index.html
A9: CAN-008 | B9: cancelar | C9: sinónimo o frase principal | D9: anular reserva | E9: Necesito dejar sin efecto la reserva que hice | F9: Alta | G9: formal | H9: General | I9: cita existente, motivo, política de cancelación, pago/abono | J9: Buscar cita existente y pedir confirmación antes de cancelar | K9: Activar cancelar si hay verbo de eliminación/anulación/no asistencia aplicado a cita/reserva/hora | L9: Variante diferenciada para evitar duplicados exactos en el conjunto de ejemplos. | M9: https://help.reservio.com/es/articles/5113819-cancelar-una-reserva-citas-individuales
A10: CAN-009 | B10: cancelar | C10: sinónimo o frase principal | D10: eliminar cita | E10: Por favor eliminar mi cita | F10: Media | G10: formal | H10: General | I10: cita existente, motivo, política de cancelación, pago/abono | J10: Buscar cita existente y pedir confirmación antes de cancelar | K10: Activar cancelar si hay verbo de eliminación/anulación/no asistencia aplicado a cita/reserva/hora | L10: Debe requerir confirmación explícita antes de ejecutar acción irreversible | M10: https://help.reservio.com/es/articles/5113819-cancelar-una-reserva-citas-individuales
A11: CAN-010 | B11: cancelar | C11: sinónimo o frase principal | D11: eliminar reserva | E11: Quiero eliminar la reserva | F11: Alta | G11: formal | H11: General | I11: cita existente, motivo, política de cancelación, pago/abono | J11: Buscar cita existente y pedir confirmación antes de cancelar | K11: Activar cancelar si hay verbo de eliminación/anulación/no asistencia aplicado a cita/reserva/hora | L11: Debe requerir confirmación explícita antes de ejecutar acción irreversible | M11: https://help.reservio.com/es/articles/5113819-cancelar-una-reserva-citas-individuales
A12: CAN-011 | B12: cancelar | C12: sinónimo o frase principal | D12: borrar cita | E12: Borrar mi cita por favor | F12: Media | G12: coloquial | H12: General | I12: cita existente, motivo, política de cancelación, pago/abono | J12: Buscar cita existente y pedir confirmación antes de cancelar | K12: Activar cancelar si hay verbo de eliminación/anulación/no asistencia aplicado a cita/reserva/hora | L12: Debe requerir confirmación explícita antes de ejecutar acción irreversible | M12: https://agendapro.com/blog/confirmaciones-automaticas-por-whatsapp/
... A68: CAN-067 | B68: cancelar | C68: señal temporal urgencia o motivo | D68: sin reprogramar | E68: Quiero cancelar sin reprogramar | F68: Alta | G68: intención compuesta | H68: WhatsApp / General | I68: motivo, cita existente, fecha/hora, pago/abono | J68: Validar política de cancelación y confirmar | K68: Si hay cancelación explícita y no hay nueva fecha/hora, activar cancelar | L68: Puede implicar penalización, devolución o derivación humana | M68: https://biz.booksy.com/es-es/blog/politica-de-cancelacion-y-no-show-para-salones

Sheet Taxonomia_Intenciones
A1: ID | B1: Intención | C1: Dominio | D1: Tipo | E1: Definición | F1: Ejemplos típicos | G1: Entidades mínimas | H1: Estado aplicable | I1: Acción segura | J1: Confirmación requerida | K1: Prioridad | L1: ¿Usar como clase? | M1: Observaciones | N1: Fuente URL
A2: INT-001 | B2: saludar | C2: conversación | D2: social | E2: Inicio o reanudación cordial de la conversación | F2: Hola | Buenas | Hola, ¿cómo están? | G2: ninguna | H2: INICIO | I2: Responder bienvenida y mostrar capacidades | J2: No | K2: Media | L2: Sí | M2: No crear reserva por un saludo aislado | N2: https://respond.io/es/blog/whatsapp-appointment-booking
A3: INT-002 | B3: despedirse | C3: conversación | D3: social | E3: Cierre cordial de la conversación | F3: Gracias, chao | Nos vemos | Hasta luego | G3: ninguna | H3: CUALQUIERA | I3: Cerrar sin ejecutar acciones | J3: No | K3: Baja | L3: Sí | M3: Mantener la conversación disponible si vuelve a escribir | N3: https://respond.io/es/blog/whatsapp-appointment-booking
A4: INT-003 | B4: agradecer | C4: conversación | D4: social | E4: Agradecimiento sin solicitud adicional | F4: Gracias | Muchas gracias | Se pasaron | G4: ninguna | H4: CUALQUIERA | I4: Responder de forma breve | J4: No | K4: Baja | L4: Sí | M4: No confundir con confirmación | N4: https://respond.io/es/blog/whatsapp-appointment-booking
A5: INT-004 | B5: solicitar_ayuda | C5: conversación | D5: soporte | E5: El cliente pregunta qué puede hacer el asistente | F5: ¿Qué puedes hacer? | Ayúdame | No sé cómo reservar | G5: ninguna | H5: INICIO | I5: Explicar opciones disponibles | J5: No | K5: Media | L5: Sí | M5: Ofrecer botones o lista cuando estén disponibles | N5: https://respond.io/es/blog/whatsapp-appointment-booking
A6: INT-005 | B6: consultar_servicios | C6: información | D6: consulta | E6: Solicita catálogo o tipos de atención | F6: ¿Qué servicios tienen? | ¿Hacen limpieza facial? | G6: empresa, sucursal opcional | H6: INICIO | I6: Consultar catálogo activo por empresa y sucursal | J6: No | K6: Alta | L6: Sí | M6: No iniciar reserva hasta que el cliente manifieste intención | N6: https://agendapro.com/blog/transformar-conversaciones-de-whatsapp-en-reservas/
A7: INT-006 | B7: consultar_precio | C7: información | D7: consulta | E7: Consulta valor de un servicio o promoción | F7: ¿Cuánto sale? | Precio de depilación | G7: servicio, sucursal opcional | H7: INICIO | I7: Consultar tarifa vigente | J7: No | K7: Alta | L7: Sí | M7: Si el servicio es ambiguo, pedir precisión | N7: https://agendapro.com/blog/transformar-conversaciones-de-whatsapp-en-reservas/
A8: INT-007 | B8: consultar_duracion | C8: información | D8: consulta | E8: Consulta cuánto dura una atención | F8: ¿Cuánto demora? | ¿Cuánto dura el masaje? | G8: servicio | H8: INICIO | I8: Responder duración configurada | J8: No | K8: Media | L8: Sí | M8: Distinguir duración de atención y tiempo de espera | N8: https://help.acuityscheduling.com/hc/es/articles/16676869573645-C%C3%B3mo-reservan-citas-los-clientes
A9: INT-008 | B9: consultar_promocion | C9: información | D9: consulta | E9: Consulta descuentos o campañas vigentes | F9: ¿Tienen promociones? | ¿Sigue el descuento? | G9: servicio opcional, sucursal opcional | H9: INICIO | I9: Consultar promociones activas y vigentes | J9: No | K9: Media | L9: Sí | M9: No inventar promociones | N9: https://agendapro.com/blog/transformar-conversaciones-de-whatsapp-en-reservas/
A10: INT-009 | B10: consultar_sucursales | C10: información | D10: consulta | E10: Consulta sedes disponibles | F10: ¿Dónde tienen sucursales? | ¿Atienden en Providencia? | G10: empresa | H10: INICIO | I10: Listar sedes públicas activas | J10: No | K10: Media | L10: Sí | M10: Ocultar sedes inactivas | N10: https://agendapro.com/blog/transformar-conversaciones-de-whatsapp-en-reservas/
A11: INT-010 | B11: consultar_direccion | C11: información | D11: consulta | E11: Solicita dirección o mapa de una sede | F11: Mándame la dirección | ¿Cómo llego? | G11: sucursal | H11: INICIO | I11: Responder dirección y enlace de mapa | J11: No | K11: Media | L11: Sí | M11: Pedir sede cuando existan varias | N11: https://agendapro.com/blog/transformar-conversaciones-de-whatsapp-en-reservas/
A12: INT-011 | B12: consultar_horario_empresa | C12: información | D12: consulta | E12: Consulta horario de atención de la empresa o sede | F12: ¿Abren el sábado? | ¿Hasta qué hora atienden? | G12: sucursal, fecha opcional | H12: INICIO | I12: Consultar horario comercial y excepciones | J12: No | K12: Media | L12: Sí | M12: No equivale a disponibilidad de agenda | N12: https://help.acuityscheduling.com/hc/es/articles/16676869573645-C%C3%B3mo-reservan-citas-los-clientes
... A43: INT-042 | B43: consultar_politica_cancelacion | C43: agenda | D43: consulta | E43: Pregunta condiciones, plazo, costo o devolución antes de cancelar | F43: ¿Hasta cuándo puedo cancelar? | ¿Pierdo el abono? | G43: empresa, servicio o reserva opcional | H43: INICIO | I43: Responder política configurada y derivar excepciones | J43: No | K43: Alta | L43: Sí | M43: No inferir una cancelación por consultar la política | N43: https://biz.booksy.com/es-es/blog/politica-de-cancelacion-y-no-show-para-salones

Sheet Ejemplos_Ampliados
A1: ID | B1: Intención esperada | C1: Tipo | D1: Mensaje del cliente | E1: Contexto anterior | F1: Entidades esperadas | G1: Respuesta o decisión esperada | H1: Acción técnica | I1: Estado relacionado | J1: Confianza esperada | K1: No clasificar como | L1: Región | M1: Fuente URL | N1: Conjunto | O1: Observaciones
A2: EAD-0001 | B2: saludar | C2: social | D2: Hola | F2: ninguna | G2: Responder bienvenida y mostrar capacidades | H2: Aplicar regla de negocio y consultar datos reales cuando corresponda | I2: INICIO | J2: Media | L2: Chile / es-419 | M2: https://respond.io/es/blog/whatsapp-appointment-booking | N2: entrenamiento | O2: No crear reserva por un saludo aislado
A3: EAD-0002 | B3: saludar | C3: social | D3: Buenas tardes | F3: ninguna | G3: Responder bienvenida y mostrar capacidades | H3: Aplicar regla de negocio y consultar datos reales cuando corresponda | I3: INICIO | J3: Media | L3: Chile / es-419 | M3: https://respond.io/es/blog/whatsapp-appointment-booking | N3: entrenamiento | O3: No crear reserva por un saludo aislado
A4: EAD-0003 | B4: saludar | C4: social | D4: Hola, ¿cómo están? | F4: ninguna | G4: Responder bienvenida y mostrar capacidades | H4: Aplicar regla de negocio y consultar datos reales cuando corresponda | I4: INICIO | J4: Media | L4: Chile / es-419 | M4: https://respond.io/es/blog/whatsapp-appointment-booking | N4: validación | O4: No crear reserva por un saludo aislado
A5: EAD-0004 | B5: saludar | C5: social | D5: Buen día, necesito una información | F5: ninguna | G5: Responder bienvenida y mostrar capacidades | H5: Aplicar regla de negocio y consultar datos reales cuando corresponda | I5: INICIO | J5: Media | L5: Chile / es-419 | M5: https://respond.io/es/blog/whatsapp-appointment-booking | N5: prueba | O5: No crear reserva por un saludo aislado
A6: EAD-0005 | B6: despedirse | C6: social | D6: Gracias, chao | F6: ninguna | G6: Cerrar sin ejecutar acciones | H6: Aplicar regla de negocio y consultar datos reales cuando corresponda | I6: CUALQUIERA | J6: Media | L6: Chile / es-419 | M6: https://respond.io/es/blog/whatsapp-appointment-booking | N6: entrenamiento | O6: Mantener la conversación disponible si vuelve a escribir
A7: EAD-0006 | B7: despedirse | C7: social | D7: Hasta luego | F7: ninguna | G7: Cerrar sin ejecutar acciones | H7: Aplicar regla de negocio y consultar datos reales cuando corresponda | I7: CUALQUIERA | J7: Media | L7: Chile / es-419 | M7: https://respond.io/es/blog/whatsapp-appointment-booking | N7: entrenamiento | O7: Mantener la conversación disponible si vuelve a escribir
A8: EAD-0007 | B8: despedirse | C8: social | D8: Eso era todo, muchas gracias | F8: ninguna | G8: Cerrar sin ejecutar acciones | H8: Aplicar regla de negocio y consultar datos reales cuando corresponda | I8: CUALQUIERA | J8: Media | L8: Chile / es-419 | M8: https://respond.io/es/blog/whatsapp-appointment-booking | N8: validación | O8: Mantener la conversación disponible si vuelve a escribir
A9: EAD-0008 | B9: despedirse | C9: social | D9: Nos vemos, que estén bien | F9: ninguna | G9: Cerrar sin ejecutar acciones | H9: Aplicar regla de negocio y consultar datos reales cuando corresponda | I9: CUALQUIERA | J9: Media | L9: Chile / es-419 | M9: https://respond.io/es/blog/whatsapp-appointment-booking | N9: prueba | O9: Mantener la conversación disponible si vuelve a escribir
A10: EAD-0009 | B10: agradecer | C10: social | D10: Gracias | F10: ninguna | G10: Responder de forma breve | H10: Aplicar regla de negocio y consultar datos reales cuando corresponda | I10: CUALQUIERA | J10: Media | L10: Chile / es-419 | M10: https://respond.io/es/blog/whatsapp-appointment-booking | N10: entrenamiento | O10: No confundir con confirmación
A11: EAD-0010 | B11: agradecer | C11: social | D11: Muchas gracias por la ayuda | F11: ninguna | G11: Responder de forma breve | H11: Aplicar regla de negocio y consultar datos reales cuando corresponda | I11: CUALQUIERA | J11: Media | L11: Chile / es-419 | M11: https://respond.io/es/blog/whatsapp-appointment-booking | N11: entrenamiento | O11: No confundir con confirmación
A12: EAD-0011 | B12: agradecer | C12: social | D12: Perfecto, se pasaron | F12: ninguna | G12: Responder de forma breve | H12: Aplicar regla de negocio y consultar datos reales cuando corresponda | I12: CUALQUIERA | J12: Media | L12: Chile / es-419 | M12: https://respond.io/es/blog/whatsapp-appointment-booking | N12: validación | O12: No confundir con confirmación
A13: EAD-0012 | B13: agradecer | C13: social | D13: Vale, gracias por responder | F13: ninguna | G13: Responder de forma breve | H13: Aplicar regla de negocio y consultar datos reales cuando corresponda | I13: CUALQUIERA | J13: Media | L13: Chile / es-419 | M13: https://respond.io/es/blog/whatsapp-appointment-booking | N13: prueba | O13: No confundir con confirmación
... A21: EAD-0020 | B21: consultar_servicios | C21: consulta | D21: ¿Atienden depilación láser? | F21: empresa, sucursal opcional | G21: Consultar catálogo activo por empresa y sucursal | H21: Aplicar regla de negocio y consultar datos reales cuando corresponda | I21: INICIO | J21: Alta | L21: Chile / es-419 | M21: https://agendapro.com/blog/transformar-conversaciones-de-whatsapp-en-reservas/ | N21: prueba | O21: No iniciar reserva hasta que el cliente manifieste intención
A22: EAD-0021 | B22: consultar_precio | C22: consulta | D22: ¿Cuánto cuesta la limpieza facial? | F22: servicio, sucursal opcional | G22: Consultar tarifa vigente | H22: Aplicar regla de negocio y consultar datos reales cuando corresponda | I22: INICIO | J22: Alta | K22: reservar | L22: Chile / es-419 | M22: https://agendapro.com/blog/transformar-conversaciones-de-whatsapp-en-reservas/ | N22: entrenamiento | O22: Si el servicio es ambiguo, pedir precisión
A23: EAD-0022 | B23: consultar_precio | C23: consulta | D23: Precio del masaje descontracturante | F23: servicio, sucursal opcional | G23: Consultar tarifa vigente | H23: Aplicar regla de negocio y consultar datos reales cuando corresponda | I23: INICIO | J23: Alta | K23: reservar | L23: Chile / es-419 | M23: https://agendapro.com/blog/transformar-conversaciones-de-whatsapp-en-reservas/ | N23: entrenamiento | O23: Si el servicio es ambiguo, pedir precisión
A24: EAD-0023 | B24: consultar_precio | C24: consulta | D24: ¿En cuánto sale ese tratamiento? | F24: servicio, sucursal opcional | G24: Consultar tarifa vigente | H24: Aplicar regla de negocio y consultar datos reales cuando corresponda | I24: INICIO | J24: Alta | K24: reservar | L24: Chile / es-419 | M24: https://agendapro.com/blog/transformar-conversaciones-de-whatsapp-en-reservas/ | N24: validación | O24: Si el servicio es ambiguo, pedir precisión
A25: EAD-0024 | B25: consultar_precio | C25: consulta | D25: ¿Cuál es el valor con Carla? | F25: servicio, sucursal opcional | G25: Consultar tarifa vigente | H25: Aplicar regla de negocio y consultar datos reales cuando corresponda | I25: INICIO | J25: Alta | K25: reservar | L25: Chile / es-419 | M25: https://agendapro.com/blog/transformar-conversaciones-de-whatsapp-en-reservas/ | N25: prueba | O25: Si el servicio es ambiguo, pedir precisión
A26: EAD-0025 | B26: consultar_duracion | C26: consulta | D26: ¿Cuánto dura el masaje? | F26: servicio | G26: Responder duración configurada | H26: Aplicar regla de negocio y consultar datos reales cuando corresponda | I26: INICIO | J26: Media | L26: Chile / es-419 | M26: https://help.acuityscheduling.com/hc/es/articles/16676869573645-C%C3%B3mo-reservan-citas-los-clientes | N26: entrenamiento | O26: Distinguir duración de atención y tiempo de espera
A27: EAD-0026 | B27: consultar_duracion | C27: consulta | D27: ¿Cuánto se demora una limpieza facial? | F27: servicio | G27: Responder duración configurada | H27: Aplicar regla de negocio y consultar datos reales cuando corresponda | I27: INICIO | J27: Media | L27: Chile / es-419 | M27: https://help.acuityscheduling.com/hc/es/articles/16676869573645-C%C3%B3mo-reservan-citas-los-clientes | N27: entrenamiento | O27: Distinguir duración de atención y tiempo de espera
A28: EAD-0027 | B28: consultar_duracion | C28: consulta | D28: ¿La sesión es de una hora? | F28: servicio | G28: Responder duración configurada | H28: Aplicar regla de negocio y consultar datos reales cuando corresponda | I28: INICIO | J28: Media | L28: Chile / es-419 | M28: https://help.acuityscheduling.com/hc/es/articles/16676869573645-C%C3%B3mo-reservan-citas-los-clientes | N28: validación | O28: Distinguir duración de atención y tiempo de espera
A29: EAD-0028 | B29: consultar_duracion | C29: consulta | D29: Necesito saber la duración del tratamiento | F29: servicio | G29: Responder duración configurada | H29: Aplicar regla de negocio y consultar datos reales cuando corresponda | I29: INICIO | J29: Media | L29: Chile / es-419 | M29: https://help.acuityscheduling.com/hc/es/articles/16676869573645-C%C3%B3mo-reservan-citas-los-clientes | N29: prueba | O29: Distinguir duración de atención y tiempo de espera
A30: EAD-0029 | B30: consultar_promocion | C30: consulta | D30: ¿Tienen promociones este mes? | F30: servicio opcional, sucursal opcional | G30: Consultar promociones activas y vigentes | H30: Aplicar regla de negocio y consultar datos reales cuando corresponda | I30: INICIO | J30: Media | L30: Chile / es-419 | M30: https://agendapro.com/blog/transformar-conversaciones-de-whatsapp-en-reservas/ | N30: entrenamiento | O30: No inventar promociones
A31: EAD-0030 | B31: consultar_promocion | C31: consulta | D31: ¿Sigue vigente el descuento de depilación? | F31: servicio opcional, sucursal opcional | G31: Consultar promociones activas y vigentes | H31: Aplicar regla de negocio y consultar datos reales cuando corresponda | I31: INICIO | J31: Media | L31: Chile / es-419 | M31: https://agendapro.com/blog/transformar-conversaciones-de-whatsapp-en-reservas/ | N31: entrenamiento | O31: No inventar promociones
A32: EAD-0031 | B32: consultar_promocion | C32: consulta | D32: Muéstrame las ofertas | F32: servicio opcional, sucursal opcional | G32: Consultar promociones activas y vigentes | H32: Aplicar regla de negocio y consultar datos reales cuando corresponda | I32: INICIO | J32: Media | L32: Chile / es-419 | M32: https://agendapro.com/blog/transformar-conversaciones-de-whatsapp-en-reservas/ | N32: validación | O32: No inventar promociones
A33: EAD-0032 | B33: consultar_promocion | C33: consulta | D33: ¿Hay precio especial por varias sesiones? | F33: servicio opcional, sucursal opcional | G33: Consultar promociones activas y vigentes | H33: Aplicar regla de negocio y consultar datos reales cuando corresponda | I33: INICIO | J33: Media | L33: Chile / es-419 | M33: https://agendapro.com/blog/transformar-conversaciones-de-whatsapp-en-reservas/ | N33: prueba | O33: No inventar promociones
A34: EAD-0033 | B34: consultar_sucursales | C34: consulta | D34: ¿Qué sucursales tienen? | F34: empresa | G34: Listar sedes públicas activas | H34: Aplicar regla de negocio y consultar datos reales cuando corresponda | I34: INICIO | J34: Media | L34: Chile / es-419 | M34: https://agendapro.com/blog/transformar-conversaciones-de-whatsapp-en-reservas/ | N34: entrenamiento | O34: Ocultar sedes inactivas
A35: EAD-0034 | B35: consultar_sucursales | C35: consulta | D35: ¿Atienden en Providencia? | F35: empresa | G35: Listar sedes públicas activas | H35: Aplicar regla de negocio y consultar datos reales cuando corresponda | I35: INICIO | J35: Media | L35: Chile / es-419 | M35: https://agendapro.com/blog/transformar-conversaciones-de-whatsapp-en-reservas/ | N35: entrenamiento | O35: Ocultar sedes inactivas
A36: EAD-0035 | B36: consultar_sucursales | C36: consulta | D36: ¿Tienen local en Las Condes? | F36: empresa | G36: Listar sedes públicas activas | H36: Aplicar regla de negocio y consultar datos reales cuando corresponda | I36: INICIO | J36: Media | L36: Chile / es-419 | M36: https://agendapro.com/blog/transformar-conversaciones-de-whatsapp-en-reservas/ | N36: validación | O36: Ocultar sedes inactivas
A37: EAD-0036 | B37: consultar_sucursales | C37: consulta | D37: ¿Cuál sede me queda más cerca de Ñuñoa? | F37: empresa | G37: Listar sedes públicas activas | H37: Aplicar regla de negocio y consultar datos reales cuando corresponda | I37: INICIO | J37: Media | L37: Chile / es-419 | M37: https://agendapro.com/blog/transformar-conversaciones-de-whatsapp-en-reservas/ | N37: prueba | O37: Ocultar sedes inactivas
... A49: EAD-0048 | B49: consultar_profesionales | C49: consulta | D49: ¿Puedo ver los especialistas disponibles? | F49: servicio, sucursal, fecha opcional | G49: Listar profesionales habilitados | H49: Aplicar regla de negocio y consultar datos reales cuando corresponda | I49: INICIO | J49: Alta | L49: Chile / es-419 | M49: https://help.acuityscheduling.com/hc/es/articles/16676869573645-C%C3%B3mo-reservan-citas-los-clientes | N49: prueba | O49: Filtrar por empresa, sede y servicio
A50: EAD-0049 | B50: consultar_disponibilidad | C50: consulta | D50: ¿Qué horas hay mañana para masaje? | F50: servicio, sucursal, profesional, fecha | G50: Consultar disponibilidad y ofrecer alternativas | H50: Aplicar regla de negocio y consultar datos reales cuando corresponda | I50: INICIO | J50: Alta | K50: reservar | L50: Chile / es-419 | M50: https://respond.io/es/blog/whatsapp-appointment-booking | N50: entrenamiento | O50: No bloquear un cupo hasta que se seleccione
A51: EAD-0050 | B51: consultar_disponibilidad | C51: consulta | D51: ¿Tienen cupo hoy en la tarde? | F51: servicio, sucursal, profesional, fecha | G51: Consultar disponibilidad y ofrecer alternativas | H51: Aplicar regla de negocio y consultar datos reales cuando corresponda | I51: INICIO | J51: Alta | K51: reservar | L51: Chile / es-419 | M51: https://respond.io/es/blog/whatsapp-appointment-booking | N51: entrenamiento | O51: No bloquear un cupo hasta que se seleccione
A52: EAD-0051 | B52: consultar_disponibilidad | C52: consulta | D52: Disponibilidad con Carla el viernes | F52: servicio, sucursal, profesional, fecha | G52: Consultar disponibilidad y ofrecer alternativas | H52: Aplicar regla de negocio y consultar datos reales cuando corresponda | I52: INICIO | J52: Alta | K52: reservar | L52: Chile / es-419 | M52: https://respond.io/es/blog/whatsapp-appointment-booking | N52: validación | O52: No bloquear un cupo hasta que se seleccione
A53: EAD-0052 | B53: consultar_disponibilidad | C53: consulta | D53: Solo quiero saber si queda alguna hora esta semana | F53: servicio, sucursal, profesional, fecha | G53: Consultar disponibilidad y ofrecer alternativas | H53: Aplicar regla de negocio y consultar datos reales cuando corresponda | I53: INICIO | J53: Alta | K53: reservar | L53: Chile / es-419 | M53: https://respond.io/es/blog/whatsapp-appointment-booking | N53: prueba | O53: No bloquear un cupo hasta que se seleccione
A54: EAD-0053 | B54: reservar | C54: acción | D54: Quiero reservar una limpieza facial mañana | F54: servicio, sucursal, profesional, fecha, hora, cliente | G54: Completar datos, bloquear temporalmente y confirmar | H54: Aplicar regla de negocio y consultar datos reales cuando corresponda | I54: INICIO | J54: Alta | L54: Chile / es-419 | M54: https://help.reservio.com/es/articles/5113656-como-crear-reservas-para-citas-individuales | N54: entrenamiento | O54: La creación definitiva requiere validación transaccional
A55: EAD-0054 | B55: reservar | C55: acción | D55: Necesito pedir hora en Providencia | F55: servicio, sucursal, profesional, fecha, hora, cliente | G55: Completar datos, bloquear temporalmente y confirmar | H55: Aplicar regla de negocio y consultar datos reales cuando corresponda | I55: INICIO | J55: Alta | L55: Chile / es-419 | M55: https://help.reservio.com/es/articles/5113656-como-crear-reservas-para-citas-individuales | N55: entrenamiento | O55: La creación definitiva requiere validación transaccional
A56: EAD-0055 | B56: reservar | C56: acción | D56: Agéndame con Carla el viernes a las cuatro | F56: servicio, sucursal, profesional, fecha, hora, cliente | G56: Completar datos, bloquear temporalmente y confirmar | H56: Aplicar regla de negocio y consultar datos reales cuando corresponda | I56: INICIO | J56: Alta | L56: Chile / es-419 | M56: https://help.reservio.com/es/articles/5113656-como-crear-reservas-para-citas-individuales | N56: validación | O56: La creación definitiva requiere validación transaccional
A57: EAD-0056 | B57: reservar | C57: acción | D57: Quisiera una cita para depilación la próxima semana | F57: servicio, sucursal, profesional, fecha, hora, cliente | G57: Completar datos, bloquear temporalmente y confirmar | H57: Aplicar regla de negocio y consultar datos reales cuando corresponda | I57: INICIO | J57: Alta | L57: Chile / es-419 | M57: https://help.reservio.com/es/articles/5113656-como-crear-reservas-para-citas-individuales | N57: prueba | O57: La creación definitiva requiere validación transaccional
A58: EAD-0057 | B58: seleccionar_servicio | C58: selección | D58: La limpieza facial | E58: Asistente solicitó una respuesta en estado ESPERANDO_SERVICIO | F58: service_id o referencia contextual | G58: Resolver selección y continuar | H58: Aplicar regla de negocio y consultar datos reales cuando corresponda | I58: ESPERANDO_SERVICIO | J58: Alta | L58: Chile / es-419 | M58: https://respond.io/es/blog/whatsapp-appointment-booking | N58: entrenamiento | O58: Validar que el servicio pertenezca a la empresa
...

Sheet Escenarios_Multiturno
A1: Escenario ID | B1: Nombre | C1: Categoría | D1: Precondiciones | E1: Cantidad de turnos | F1: Resultado final esperado | G1: Prioridad | H1: Riesgo principal | I1: Etiquetas | J1: Fuente URL
A2: ESC-001 | B2: Reserva completa en un solo mensaje | C2: Reserva | D2: Empresa y sucursal activas; servicio disponible | E2: 4 | F2: Reserva confirmada sin preguntas innecesarias | G2: Crítica | H2: Doble reserva o fecha mal normalizada | I2: reserva;datos_completos;confirmacion | J2: https://respond.io/es/blog/whatsapp-appointment-booking
A3: ESC-002 | B3: Reserva sin servicio | C3: Reserva | D3: Catálogo activo con varios servicios | E3: 5 | F3: Flujo continúa solo después de completar servicio y sede | G3: Alta | H3: Ofrecer horarios de un servicio incorrecto | I3: reserva;dato_faltante | J3: https://respond.io/es/blog/whatsapp-appointment-booking
A4: ESC-003 | B4: Varias sucursales y referencia ordinal | C4: Reserva | D4: Dos sedes activas ofrecen el mismo servicio | E4: 3 | F4: Sucursal Las Condes seleccionada sin confundirla con un horario | G4: Alta | H4: Resolver ordinal contra una lista antigua | I4: contexto;ordinal;sucursal | J4: https://respond.io/es/blog/whatsapp-appointment-booking
A5: ESC-004 | B5: Profesional específico sin disponibilidad | C5: Reserva | D5: Profesional activo, habilitado para servicio, sin cupo en fecha | E5: 3 | F5: Se respeta preferencia profesional y se ofrece fecha alternativa | G5: Crítica | H5: Cambiar profesional sin consentimiento | I5: profesional;sin_disponibilidad;alternativas | J5: https://respond.io/es/blog/whatsapp-appointment-booking
A6: ESC-005 | B6: Cualquier profesional disponible | C6: Reserva | D6: Varios profesionales habilitados | E6: 3 | F6: Se asigna el profesional asociado al horario seleccionado | G6: Crítica | H6: Guardar “cualquiera” como profesional definitivo | I6: profesional_cualquiera;slot | J6: https://respond.io/es/blog/whatsapp-appointment-booking
A7: ESC-006 | B7: Servicio no ofrecido por la sede | C7: Reserva | D7: Servicio activo en otra sede | E7: 2 | F7: No se consulta disponibilidad en una relación inválida | G7: Crítica | H7: Reserva en sede que no presta el servicio | I7: sucursal;servicio;incompatibilidad | J7: https://respond.io/es/blog/whatsapp-appointment-booking
A8: ESC-007 | B8: Sin cupos en la fecha solicitada | C8: Disponibilidad | D8: Servicio y sede válidos; agenda completa | E8: 3 | F8: Consulta cerrada sin reserva ni retención | G8: Alta | H8: Crear una reserva por consultar disponibilidad | I8: consulta;sin_cupo;no_reservar | J8: https://respond.io/es/blog/whatsapp-appointment-booking
A9: ESC-008 | B9: Fecha relativa ambigua | C9: Reserva | D9: Zona horaria de la empresa configurada | E9: 3 | F9: La fecha queda explícitamente normalizada | G9: Alta | H9: Agendar una semana equivocada | I9: fecha_relativa;aclaracion | J9: https://respond.io/es/blog/whatsapp-appointment-booking
A10: ESC-009 | B10: Fecha en el pasado | C10: Reserva | D10: Fecha actual conocida en zona horaria de sede | E10: 2 | F10: No se crea ni consulta un cupo pasado | G10: Crítica | H10: Datos temporalmente inválidos | I10: fecha_pasada;validacion | J10: https://respond.io/es/blog/whatsapp-appointment-booking
A11: ESC-010 | B11: Horario fuera de atención | C11: Reserva | D11: Sede cierra a las 20:00 | E11: 2 | F11: Solo se ofrecen horarios dentro de la jornada | G11: Crítica | H11: Reservar fuera del horario comercial | I11: horario_sede;fuera_de_rango | J11: https://respond.io/es/blog/whatsapp-appointment-booking
A12: ESC-011 | B12: Selección de horario vencido | C12: Reserva | D12: El cupo fue ofrecido pero otro cliente lo tomó | E12: 3 | F12: No se produce doble reserva | G12: Crítica | H12: Confiar en una lista de disponibilidad antigua | I12: concurrencia;slot_vencido | J12: https://respond.io/es/blog/whatsapp-appointment-booking
A13: ESC-012 | B13: Retención temporal expirada | C13: Reserva | D13: Existe una retención de cupo expirada | E13: 3 | F13: El cliente debe seleccionar un cupo vigente | G13: Crítica | H13: Crear desde una retención vencida | I13: retencion;expiracion | J13: https://respond.io/es/blog/whatsapp-appointment-booking
... A37: ESC-036 | B37: Derivación humana conserva el progreso | C37: Soporte | D37: Reserva iniciada con servicio, sede y fecha | E37: 3 | F37: El agente recibe contexto y el asistente deja de ejecutar acciones | G37: Crítica | H37: Respuestas dobles o pérdida de contexto | I37: derivacion;agente;contexto | J37: https://respond.io/es/blog/whatsapp-appointment-booking

Sheet Conversaciones_Multiturno
A1: Escenario ID | B1: Escenario | C1: Turno | D1: Emisor | E1: Mensaje | F1: Intención detectada | G1: Estado antes | H1: Entidades nuevas | I1: Datos acumulados | J1: Acción del servidor | K1: Respuesta o decisión esperada | L1: Estado después | M1: Resultado final | N1: Prioridad | O1: Etiquetas
A2: ESC-001 | B2: Reserva completa en un solo mensaje | C2: 1 | D2: Cliente | E2: Hola, quiero una limpieza facial mañana a las 16:00 en Providencia con cualquiera | F2: reservar | G2: INICIO | H2: servicio=limpieza facial; fecha=mañana; hora=16:00; sucursal=Providencia; profesional=cualquiera | I2: servicio, fecha, hora, sucursal y preferencia profesional | J2: Resolver fecha absoluta y consultar cupo | K2: Validar disponibilidad y mostrar resumen | L2: ESPERANDO_CONFIRMACION_RESERVA | N2: Crítica | O2: reserva;datos_completos;confirmacion
A3: ESC-001 | B3: Reserva completa en un solo mensaje | C3: 2 | D3: Asistente | E3: Tengo disponibilidad mañana a las 16:00 en Providencia. Duración 60 minutos. ¿Confirmas? | G3: ESPERANDO_CONFIRMACION_RESERVA | I3: servicio, fecha, hora, sucursal y preferencia profesional | K3: Esperar confirmación explícita | L3: ESPERANDO_CONFIRMACION_RESERVA | N3: Crítica | O3: reserva;datos_completos;confirmacion
A4: ESC-001 | B4: Reserva completa en un solo mensaje | C4: 3 | D4: Cliente | E4: Sí, confirmo | F4: confirmar_reserva | G4: ESPERANDO_CONFIRMACION_RESERVA | I4: servicio, fecha, hora, sucursal y preferencia profesional | J4: Crear reserva idempotente | K4: Confirmar código, fecha, hora, sede y profesional asignado | L4: RESERVA_CONFIRMADA | N4: Crítica | O4: reserva;datos_completos;confirmacion
A5: ESC-001 | B5: Reserva completa en un solo mensaje | C5: 4 | D5: Asistente | E5: Tu reserva quedó confirmada para mañana a las 16:00 en Providencia. | G5: RESERVA_CONFIRMADA | I5: servicio, fecha, hora, sucursal y preferencia profesional | L5: RESERVA_CONFIRMADA | M5: Reserva confirmada sin preguntas innecesarias | N5: Crítica | O5: reserva;datos_completos;confirmacion
A6: ESC-002 | B6: Reserva sin servicio | C6: 1 | D6: Cliente | E6: Quiero pedir una hora para mañana | F6: reservar | G6: INICIO | H6: fecha=mañana | I6: fecha | J6: Detectar servicio faltante | K6: Preguntar servicio | L6: ESPERANDO_SERVICIO | N6: Alta | O6: reserva;dato_faltante
A7: ESC-002 | B7: Reserva sin servicio | C7: 2 | D7: Asistente | E7: ¿Para qué servicio deseas reservar? | G7: ESPERANDO_SERVICIO | I7: fecha | L7: ESPERANDO_SERVICIO | N7: Alta | O7: reserva;dato_faltante
A8: ESC-002 | B8: Reserva sin servicio | C8: 3 | D8: Cliente | E8: Limpieza facial | F8: seleccionar_servicio | G8: ESPERANDO_SERVICIO | H8: servicio=limpieza facial | I8: fecha y servicio | J8: Listar sedes que ofrecen el servicio | K8: Preguntar sede | L8: ESPERANDO_SUCURSAL | N8: Alta | O8: reserva;dato_faltante
A9: ESC-002 | B9: Reserva sin servicio | C9: 4 | D9: Asistente | E9: La limpieza facial está disponible en Providencia y Las Condes. ¿Qué sucursal prefieres? | G9: ESPERANDO_SUCURSAL | I9: fecha y servicio | L9: ESPERANDO_SUCURSAL | N9: Alta | O9: reserva;dato_faltante
A10: ESC-002 | B10: Reserva sin servicio | C10: 5 | D10: Cliente | E10: Providencia | F10: seleccionar_sucursal | G10: ESPERANDO_SUCURSAL | H10: sucursal=Providencia | I10: fecha, servicio y sucursal | J10: Consultar horarios | K10: Ofrecer cupos reales | L10: ESPERANDO_HORARIO | M10: Flujo continúa solo después de completar servicio y sede | N10: Alta | O10: reserva;dato_faltante
A11: ESC-003 | B11: Varias sucursales y referencia ordinal | C11: 1 | D11: Cliente | E11: Quiero depilación láser el viernes | F11: reservar | G11: INICIO | H11: servicio=depilación láser; fecha=viernes | I11: servicio y fecha | J11: Buscar sedes compatibles | K11: Listar sedes numeradas | L11: ESPERANDO_SUCURSAL | N11: Alta | O11: contexto;ordinal;sucursal
A12: ESC-003 | B12: Varias sucursales y referencia ordinal | C12: 2 | D12: Asistente | E12: Está disponible en 1) Providencia y 2) Las Condes. ¿Cuál prefieres? | G12: ESPERANDO_SUCURSAL | I12: servicio y fecha | L12: ESPERANDO_SUCURSAL | N12: Alta | O12: contexto;ordinal;sucursal
A13: ESC-003 | B13: Varias sucursales y referencia ordinal | C13: 3 | D13: Cliente | E13: La segunda | F13: seleccionar_sucursal | G13: ESPERANDO_SUCURSAL | H13: índice=2 | I13: servicio, fecha y sucursal=Las Condes | J13: Resolver índice contra la última lista | K13: Continuar con Las Condes | L13: ESPERANDO_PROFESIONAL | M13: Sucursal Las Condes seleccionada sin confundirla con un horario | N13: Alta | O13: contexto;ordinal;sucursal
A14: ESC-004 | B14: Profesional específico sin disponibilidad | C14: 1 | D14: Cliente | E14: Quiero masaje con Carla mañana en la tarde | F14: reservar | G14: INICIO | H14: servicio=masaje; profesional=Carla; fecha=mañana; franja=tarde | I14: servicio, profesional, fecha y franja | J14: Consultar agenda de Carla | K14: Informar sin cupo y ofrecer alternativas | L14: ESPERANDO_DECISION_ALTERNATIVA | N14: Crítica | O14: profesional;sin_disponibilidad;alternativas
A15: ESC-004 | B15: Profesional específico sin disponibilidad | C15: 2 | D15: Asistente | E15: Carla no tiene cupos mañana en la tarde. Puedo ofrecerte con Ana a las 16:00 o con Carla el jueves a las 17:00. | G15: ESPERANDO_DECISION_ALTERNATIVA | I15: servicio, profesional, fecha y franja | L15: ESPERANDO_HORARIO | N15: Crítica | O15: profesional;sin_disponibilidad;alternativas
A16: ESC-004 | B16: Profesional específico sin disponibilidad | C16: 3 | D16: Cliente | E16: Con Carla el jueves | F16: seleccionar_horario | G16: ESPERANDO_HORARIO | H16: profesional=Carla; fecha=jueves; hora=17:00 por contexto | I16: servicio, Carla, jueves 17:00 | J16: Validar cupo aún vigente | K16: Mostrar resumen | L16: ESPERANDO_CONFIRMACION_RESERVA | M16: Se respeta preferencia profesional y se ofrece fecha alternativa | N16: Crítica | O16: profesional;sin_disponibilidad;alternativas
A17: ESC-005 | B17: Cualquier profesional disponible | C17: 1 | D17: Cliente | E17: Quiero una limpieza facial el sábado, con cualquiera | F17: reservar | G17: INICIO | H17: servicio=limpieza facial; fecha=sábado; profesional=cualquiera | I17: servicio, fecha y profesional flexible | J17: Buscar primer cupo válido entre profesionales | K17: Ofrecer opciones con profesional identificado | L17: ESPERANDO_HORARIO | N17: Crítica | O17: profesional_cualquiera;slot
A18: ESC-005 | B18: Cualquier profesional disponible | C18: 2 | D18: Asistente | E18: Tengo 10:00 con Ana, 11:30 con Carla y 13:00 con Beatriz. ¿Cuál prefieres? | G18: ESPERANDO_HORARIO | I18: servicio, fecha y profesional flexible | L18: ESPERANDO_HORARIO | N18: Crítica | O18: profesional_cualquiera;slot
A19: ESC-005 | B19: Cualquier profesional disponible | C19: 3 | D19: Cliente | E19: La de las once y media | F19: seleccionar_horario | G19: ESPERANDO_HORARIO | H19: hora=11:30; profesional=Carla por opción | I19: sábado 11:30 con Carla | J19: Crear retención temporal | K19: Pedir confirmación | L19: ESPERANDO_CONFIRMACION_RESERVA | M19: Se asigna el profesional asociado al horario seleccionado | N19: Crítica | O19: profesional_cualquiera;slot
A20: ESC-006 | B20: Servicio no ofrecido por la sede | C20: 1 | D20: Cliente | E20: Quiero botox en la sucursal Centro | F20: reservar | G20: INICIO | H20: servicio=botox; sucursal=Centro | I20: servicio y sucursal | J20: Validar relación sede-servicio | K20: Informar incompatibilidad y ofrecer sedes válidas | L20: ESPERANDO_SUCURSAL | N20: Crítica | O20: sucursal;servicio;incompatibilidad
A21: ESC-006 | B21: Servicio no ofrecido por la sede | C21: 2 | D21: Asistente | E21: La sucursal Centro no ofrece botox. Está disponible en Providencia y Las Condes. ¿Deseas elegir una de esas sedes? | G21: ESPERANDO_SUCURSAL | I21: servicio y sucursal | L21: ESPERANDO_SUCURSAL | M21: No se consulta disponibilidad en una relación inválida | N21: Crítica | O21: sucursal;servicio;incompatibilidad
A22: ESC-007 | B22: Sin cupos en la fecha solicitada | C22: 1 | D22: Cliente | E22: ¿Tienen hora mañana para depilación? | F22: consultar_disponibilidad | G22: INICIO | H22: servicio=depilación; fecha=mañana | I22: servicio y fecha | J22: Consultar cupos | K22: Indicar sin cupo y ofrecer fechas cercanas | L22: ESPERANDO_DECISION_ALTERNATIVA | N22: Alta | O22: consulta;sin_cupo;no_reservar
A23: ESC-007 | B23: Sin cupos en la fecha solicitada | C23: 2 | D23: Asistente | E23: Mañana no quedan horas. Tengo disponibilidad el jueves a las 15:00 y el viernes a las 10:30. | G23: ESPERANDO_DECISION_ALTERNATIVA | I23: servicio y fecha | L23: ESPERANDO_HORARIO | N23: Alta | O23: consulta;sin_cupo;no_reservar
A24: ESC-007 | B24: Sin cupos en la fecha solicitada | C24: 3 | D24: Cliente | E24: Solo estaba consultando, gracias | F24: agradecer | G24: ESPERANDO_HORARIO | I24: servicio y fecha | J24: Cerrar sin retener cupos | K24: No crear reserva | L24: CERRADO | M24: Consulta cerrada sin reserva ni retención | N24: Alta | O24: consulta;sin_cupo;no_reservar
A25: ESC-008 | B25: Fecha relativa ambigua | C25: 1 | D25: Cliente | E25: Quiero una hora el próximo viernes | F25: reservar | G25: INICIO | H25: fecha_texto=próximo viernes | I25: fecha ambigua | J25: Resolver según política; detectar posible ambigüedad regional | K25: Aclarar fecha absoluta | L25: ESPERANDO_FECHA | N25: Alta | O25: fecha_relativa;aclaracion
A26: ESC-008 | B26: Fecha relativa ambigua | C26: 2 | D26: Asistente | E26: ¿Te refieres al viernes 31 de julio? | G26: ESPERANDO_FECHA | I26: fecha ambigua | L26: ESPERANDO_FECHA | N26: Alta | O26: fecha_relativa;aclaracion
A27: ESC-008 | B27: Fecha relativa ambigua | C27: 3 | D27: Cliente | E27: Sí, ese viernes | F27: seleccionar_horario | G27: ESPERANDO_FECHA | H27: fecha=2026-07-31 | I27: fecha absoluta confirmada | J27: Continuar datos faltantes | K27: Preguntar servicio | L27: ESPERANDO_SERVICIO | M27: La fecha queda explícitamente normalizada | N27: Alta | O27: fecha_relativa;aclaracion
A28: ESC-009 | B28: Fecha en el pasado | C28: 1 | D28: Cliente | E28: Agéndame para ayer a las cuatro | F28: reservar | G28: INICIO | H28: fecha=ayer; hora=16:00 | I28: fecha pasada | J28: Rechazar fecha pasada | K28: Pedir una fecha futura | L28: ESPERANDO_FECHA | N28: Crítica | O28: fecha_pasada;validacion
